Workbook

Sheet Startup Quotation
A1: SALON & TRAINING CENTER - STARTUP BUDGET QUOTATION
A2: Complete Itemized Budget Estimate for 4x6m Setup (Hair, Makeup & Training Facility)
A4: TOTAL ESTIMATED BUDGET | D4: TOTAL LINE ITEMS
A5: =E38 | D5: =COUNTA(B9:B36)-5
A8: Category | B8: Item Description | C8: Qty | D8: Unit Cost ($) | E8: Total Amount ($)
A9: 1. Hair Styling & Client Area
A10: Hair Styling | B10: Professional Hydraulic Styling Chairs | C10: 2 | D10: 180 | E10: =C10*D10
A11: Hair Styling | B11: Large Styling Mirrors (with LED backlights) | C11: 2 | D11: 120 | E11: =C11*D11
A12: Hair Styling | B12: Shampoo Wash Basin Unit (Backwash System) | C12: 1 | D12: 450 | E12: =C12*D12
A13: Hair Styling | B13: Standing / Hooded Hair Dryer & Steamer | C13: 1 | D13: 180 | E13: =C13*D13
A14: Hair Styling | B14: Professional Blow Dryers | C14: 2 | D14: 60 | E14: =C14*D14
A15: Hair Styling | B15: Hot Comb Machines & Flat Irons | C15: 2 | D15: 50 | E15: =C15*D15
A16: 2. Training & Student Setup
A17: Training | B17: Practice Mannequin Heads (Dolls for Practice) | C17: 6 | D17: 25 | E17: =C17*D17
A18: Training | B18: Table Clamps & Floor Stands for Dolls | C18: 6 | D18: 15 | E18: =C18*D18
A19: Training | B19: Whiteboard & Marker Pack | C19: 1 | D19: 45 | E19: =C19*D19
A20: Training | B20: Student Practice Tables / Desks | C20: 2 | D20: 70 | E20: =C20*D20
A21: 3. Dedicated Makeup Station
A22: Makeup | B22: Professional Vanity Makeup Table + Hollywood Mirror | C22: 1 | D22: 250 | E22: =C22*D22
A23: Makeup | B23: Adjustable High-Angle Makeup Chair / Stool | C23: 1 | D23: 100 | E23: =C23*D23
A24: Makeup | B24: Ring Light (for detailed makeup & student photos) | C24: 1 | D24: 60 | E24: =C24*D24
A25: Makeup | B25: Starter Professional Makeup Kit (Foundations, palettes, brushes) | C25: 1 | D25: 250 | E25: =C25*D25
A26: Makeup | B26: Disposable Applicators, Sponges & Brush Cleaners | C26: 1 | D26: 40 | E26: =C26*D26
A27: 4. Tools, Consumables & Hair Inventory
A28: Tools & Inventory | B28: Professional Comb Sets (Tail, wide-tooth, cutting) | C28: 3 | D28: 15 | E28: =C28*D28
A29: Tools & Inventory | B29: Professional Hair Cutting Shears & Clippers | C29: 2 | D29: 70 | E29: =C29*D29
A30: Tools & Inventory | B30: Hair Relaxers, Treatments & Dyes Stock | C30: 1 | D30: 150 | E30: =C30*D30
A31: Tools & Inventory | B31: Hair Foods, Oils, Sprays & Cosmetics Stock | C31: 1 | D31: 100 | E31: =C31*D31
A32: Tools & Inventory | B32: Braiding Hair Bundles (Synthetic & Human Hair stock) | C32: 1 | D32: 200 | E32: =C32*D32
A33: Tools & Inventory | B33: Wigs, Weaves & Wig Installation Kit (Glues, caps, removers) | C33: 1 | D33: 250 | E33: =C33*D33
A34: Tools & Inventory | B34: Nail Table, Polish Set & Basic Nail Tools | C34: 1 | D34: 150 | E34: =C34*D34
A35: Tools & Inventory | B35: Salon Towels & Client Capes | C35: 20 | D35: 5 | E35: =C35*D35
A36: 5. Plumbing, Electrical & Interior Setup
A37: Facility Setup | B37: Instant Water Heater Unit | C37: 1 | D37: 120 | E37: =C37*D37
A38: Facility Setup | B38: Plumbing Work & Piping (Sink setup & water connection) | C38: 1 | D38: 250 | E38: =C38*D38
A39: Facility Setup | B39: Heavy-Duty Wiring & Multiple Power Outlets | C39: 1 | D39: 150 | E39: =C39*D39
A40: Facility Setup | B40: Ceiling Fans / Ventilation | C40: 2 | D40: 60 | E40: =C40*D40
A41: Facility Setup | B41: Overhead LED Lighting & Spotlights | C41: 1 | D41: 100 | E41: =C41*D41
A42: Facility Setup | B42: Mobile Rolling Trolleys (for tool storage) | C42: 3 | D42: 45 | E42: =C42*D42
A43: Facility Setup | B43: Tool Sterilizer Cabinet / Barbicide Sanitizing Jars | C43: 1 | D43: 60 | E43: =C43*D43
...

Sheet Category Summary
A1: BUDGET SUMMARY BY CATEGORY
A3: Category | B3: Subtotal ($) | C3: % of Budget
A4: 1. Hair Styling & Client Area | B4: =SUM('Startup Quotation'!E10:E15) | C4: =B4/B9
A5: 2. Training & Student Setup | B5: =SUM('Startup Quotation'!E17:E20) | C5: =B5/B9
A6: 3. Dedicated Makeup Station | B6: =SUM('Startup Quotation'!E22:E26) | C6: =B6/B9
A7: 4. Tools, Consumables & Hair Inventory | B7: =SUM('Startup Quotation'!E28:E35) | C7: =B7/B9
A8: 5. Plumbing, Electrical & Interior Setup | B8: =SUM('Startup Quotation'!E37:E44) | C8: =B8/B9
A9: TOTAL | B9: =SUM(B4:B8) | C9: =SUM(C4:C8)
